[{"raw":{},"required":["Filename","Size"],"package":"python3-zope.exceptions","source":"zope.exceptions","version":"5.1-1","section":"zope","priority":"optional","architecture":"all","depends":["python3-pkg-resources","python3-zope.interface","python3:any"],"installedSize":98,"maintainer":"Debian Python Team <team+python@tracker.debian.org>","description":"Zope exceptions for Python 3","homepage":"https://github.com/zopefoundation/zope.exceptions","filename":"pool/main/z/zope.exceptions/python3-zope.exceptions_5.1-1_all.deb","size":18560,"md5":"c68b847a6201f88895a53279177d79f9","sha256":"35b9255edc2fe4d46cfa0b83f562a28025fd413f34bb68d8f4692540d523df98","descriptionMd5":"6659ed22b4d66ce3d4e50aa50de55f19"}]