{"raw":{},"required":["Filename","Size"],"package":"python3-zope.exceptions","source":"zope.exceptions","version":"5.1-2","section":"zope","priority":"optional","architecture":"all","depends":["python3-pkg-resources","python3-zope.interface","python3:any"],"installedSize":98,"maintainer":"Debian Python Team <team+python@tracker.debian.org>","description":"Zope exceptions for Python 3","homepage":"https://github.com/zopefoundation/zope.exceptions","filename":"pool/main/z/zope.exceptions/python3-zope.exceptions_5.1-2_all.deb","size":18716,"md5":"32b335d45230335b9d4e298ae6c0255a","sha256":"99379c021c09a5636bed26d61512bc7f8b1368a496f516a497b1d637d150be39","descriptionMd5":"6659ed22b4d66ce3d4e50aa50de55f19"}