{
	"raw": {},
	"required": [
		"Filename",
		"Size"
	],
	"package": "python3-zope.exceptions",
	"source": "zope.exceptions",
	"version": "6.0-1",
	"section": "zope",
	"priority": "optional",
	"architecture": "all",
	"depends": [
		"python3-pkg-resources",
		"python3-zope.interface",
		"python3:any"
	],
	"installedSize": 96,
	"maintainer": "Debian Python Team <team+python@tracker.debian.org>",
	"description": "Zope exceptions for Python 3",
	"homepage": "https://github.com/zopefoundation/zope.exceptions",
	"filename": "pool/main/z/zope.exceptions/python3-zope.exceptions_6.0-1_all.deb",
	"size": 18668,
	"md5": "1eaefbd1fcf26b6a73bcb62cc486a7dc",
	"sha256": "1ea0451115ffa0a7dc66c2586e00c1e4d61ec6ab49d6a86c6bdb10372915a600",
	"descriptionMd5": "6659ed22b4d66ce3d4e50aa50de55f19"
}