{
	"raw": {},
	"required": [
		"Filename",
		"Size"
	],
	"package": "python3-zope.exceptions",
	"source": "zope.exceptions",
	"version": "6.0-2",
	"section": "zope",
	"priority": "optional",
	"architecture": "all",
	"depends": [
		"python3-zope.interface",
		"python3:any"
	],
	"installedSize": 96,
	"maintainer": "Debian Python Team <team+python@tracker.debian.org>",
	"description": "Zope exceptions for Python 3",
	"homepage": "https://github.com/zopefoundation/zope.exceptions",
	"filename": "pool/main/z/zope.exceptions/python3-zope.exceptions_6.0-2_all.deb",
	"size": 18720,
	"md5": "1ef71cc37c21d608f1719b53989145e7",
	"sha256": "94614079a5676cf4bcbbcdf748f2a052980aa8b373daebc9b79627284870fa39",
	"descriptionMd5": "6659ed22b4d66ce3d4e50aa50de55f19"
}