{
	"raw": {},
	"required": [
		"Filename",
		"Size"
	],
	"package": "python3-zope.exceptions",
	"source": "zope.exceptions",
	"version": "4.6-1",
	"section": "zope",
	"priority": "optional",
	"architecture": "all",
	"depends": [
		"python3-pkg-resources",
		"python3-zope.interface",
		"python3:any"
	],
	"installedSize": 97,
	"maintainer": "Debian QA Group <packages@qa.debian.org>",
	"description": "Zope exceptions for Python 3",
	"homepage": "https://github.com/zopefoundation/zope.exceptions",
	"filename": "pool/main/z/zope.exceptions/python3-zope.exceptions_4.6-1_all.deb",
	"size": 18056,
	"md5": "e3a55d77be9e39a04ccafc2b63ebc9e9",
	"sha256": "481672ff2221a97c4fd6b92ac28a756e80a407a54d2a95ba944d5543dada893c",
	"descriptionMd5": "6659ed22b4d66ce3d4e50aa50de55f19"
}