[{"raw":{},"required":["Filename","Size"],"package":"python3-zope.exceptions","source":"zope.exceptions","version":"4.4-1","section":"zope","priority":"optional","architecture":"all","depends":["python3-pkg-resources","python3-zope.interface","python3:any"],"installedSize":96,"maintainer":"Debian QA Group <packages@qa.debian.org>","description":"Zope exceptions for Python 3","homepage":"http://pypi.python.org/pypi/zope.exceptions","filename":"pool/main/z/zope.exceptions/python3-zope.exceptions_4.4-1_all.deb","size":18356,"md5":"782e09d38d7600d47aa91da28f04a993","sha256":"47441c3239204ef11f3e52cbb5daf253b994d4b784e49ce945f8a97b021826f7","descriptionMd5":"6659ed22b4d66ce3d4e50aa50de55f19"}]